Traceback (most recent call last):
  File "c:\anacoda3\lib\site-packages\jupyter_cache\executors\utils.py", line 51, in single_nb_execution
    executenb(
  File "c:\anacoda3\lib\site-packages\nbclient\client.py", line 1077, in execute
    return NotebookClient(nb=nb, resources=resources, km=km, **kwargs).execute()
  File "c:\anacoda3\lib\site-packages\nbclient\util.py", line 74, in wrapped
    return just_run(coro(*args, **kwargs))
  File "c:\anacoda3\lib\site-packages\nbclient\util.py", line 53, in just_run
    return loop.run_until_complete(coro)
  File "c:\anacoda3\lib\asyncio\base_events.py", line 616, in run_until_complete
    return future.result()
  File "c:\anacoda3\lib\site-packages\nbclient\client.py", line 526, in async_execute
    await self.async_execute_cell(
  File "c:\anacoda3\lib\site-packages\nbclient\client.py", line 822, in async_execute_cell
    self._check_raise_for_error(cell, exec_reply)
  File "c:\anacoda3\lib\site-packages\nbclient\client.py", line 730, in _check_raise_for_error
    raise CellExecutionError.from_cell_and_msg(cell, exec_reply['content'])
nbclient.exceptions.CellExecutionError: An error occurred while executing the following cell:
------------------
# Âà©Áî®Â∑≤Âª∫Á´ã‰πãÊ®°ÂûãÈ†êÊ∏¨Ê∏¨Ë©¶Ë≥áÊñô‰πãÁµêÊûú(y)
y_pred = clf.predict(X_test_std)
y_pred
------------------

[1;31m---------------------------------------------------------------------------[0m
[1;31mNameError[0m                                 Traceback (most recent call last)
[1;32m<ipython-input-14-42652a82f2f4>[0m in [0;36m<module>[1;34m[0m
[0;32m      1[0m [1;31m# Âà©Áî®Â∑≤Âª∫Á´ã‰πãÊ®°ÂûãÈ†êÊ∏¨Ê∏¨Ë©¶Ë≥áÊñô‰πãÁµêÊûú(y)[0m[1;33m[0m[1;33m[0m[1;33m[0m[0m
[1;32m----> 2[1;33m [0my_pred[0m [1;33m=[0m [0mclf[0m[1;33m.[0m[0mpredict[0m[1;33m([0m[0mX_test_std[0m[1;33m)[0m[1;33m[0m[1;33m[0m[0m
[0m[0;32m      3[0m [0my_pred[0m[1;33m[0m[1;33m[0m[0m

[1;31mNameError[0m: name 'clf' is not defined
NameError: name 'clf' is not defined

